Workbook

Sheet Read Me
A1: PupBox — Customer Website Test Suite
A2: Version | B2: 1.0 · 8 October 2026
A3: Scope | B3: Customer website (apps/web): navigation, language, homepage, pricing, custom box, shop, product, cart, coupons, account access, checkout (normal and gift), payment, account area, gift claim, blog/CMS, promo popup, SEO, accessibility, responsive, performance, security. Admin panel and API-only tests are out of scope.
A4: Environment | B4: Local: website http://localhost:3000 · API http://localhost:4000/api/v1 · admin http://localhost:3001. Start with: docker compose up -d && npm run dev
A5: Built from | B5: Reading the website source on branch refactor/subscription-plans-modules plus live checks against the local stack on 8 Oct 2026. Cases reflect how the site actually works today, and what it should do where it falls short.
A7: How to use
A8: Columns to fill in | B8: Yellow columns on "Test Cases": Status, Actual Result, Defect ID, Tester, Run Date, Browser / Device. Everything else is the test definition.
A9: Status values | B9: Not Run · Pass · Fail · Blocked · N/A (drop-down). Failed rows turn red, passed green, blocked amber.
A10: Priority | B10: P1 Critical — blocks buying or exposes data; run every release. P2 High — core experience. P3 Medium. P4 Low / polish.
A11: Suggested runs | B11: Smoke (before every release): filter Priority = P1. Full regression: all rows. Mobile pass: Type = Compatibility plus Responsive module on a phone.
A12: Defects | B12: "Known Defects" lists problems already found while writing this suite. "Confirmed" = reproduced on the local site; "From code" = seen in the source, verify by running the linked test. Linked test cases carry the defect ID in the "Known Defect" column.
A13: Test data | B13: See "Test Data" for accounts to create, products with special stock levels, plans, delivery methods and coupons to set up.
A14: Example row | B14: TC-WEB-001 shows the expected way to record a run: Status Pass, Actual Result "As expected", Tester initials, date, and device.
A16: Not testable yet | B16: Real payment (Flitt keys missing — D-25) and outgoing email (no Resend key). Those cases will be Blocked until the keys are set; use Flitt sandbox keys to unblock.

Sheet Summary
A1: Test run summary
A2: Updates automatically from the Status column on "Test Cases".
A4: Module | B4: Total | C4: Pass | D4: Fail | E4: Blocked | F4: Not Run | G4: N/A | H4: Pass rate
A5: Global | B5: =COUNTIF('Test Cases'!$B$2:$B$211,$A5) | C5: =COUNTIFS('Test Cases'!$B$2:$B$211,$A5,'Test Cases'!$L$2:$L$211,"Pass") | D5: =COUNTIFS('Test Cases'!$B$2:$B$211,$A5,'Test Cases'!$L$2:$L$211,"Fail") | E5: =COUNTIFS('Test Cases'!$B$2:$B$211,$A5,'Test Cases'!$L$2:$L$211,"Blocked") | F5: =COUNTIFS('Test Cases'!$B$2:$B$211,$A5,'Test Cases'!$L$2:$L$211,"Not Run") | G5: =COUNTIFS('Test Cases'!$B$2:$B$211,$A5,'Test Cases'!$L$2:$L$211,"N/A") | H5: =IF(B5-G5-F5=0,"-",C5/(B5-G5-F5))
A6: Localization | B6: =COUNTIF('Test Cases'!$B$2:$B$211,$A6) | C6: =COUNTIFS('Test Cases'!$B$2:$B$211,$A6,'Test Cases'!$L$2:$L$211,"Pass") | D6: =COUNTIFS('Test Cases'!$B$2:$B$211,$A6,'Test Cases'!$L$2:$L$211,"Fail") | E6: =COUNTIFS('Test Cases'!$B$2:$B$211,$A6,'Test Cases'!$L$2:$L$211,"Blocked") | F6: =COUNTIFS('Test Cases'!$B$2:$B$211,$A6,'Test Cases'!$L$2:$L$211,"Not Run") | G6: =COUNTIFS('Test Cases'!$B$2:$B$211,$A6,'Test Cases'!$L$2:$L$211,"N/A") | H6: =IF(B6-G6-F6=0,"-",C6/(B6-G6-F6))
A7: Homepage | B7: =COUNTIF('Test Cases'!$B$2:$B$211,$A7) | C7: =COUNTIFS('Test Cases'!$B$2:$B$211,$A7,'Test Cases'!$L$2:$L$211,"Pass") | D7: =COUNTIFS('Test Cases'!$B$2:$B$211,$A7,'Test Cases'!$L$2:$L$211,"Fail") | E7: =COUNTIFS('Test Cases'!$B$2:$B$211,$A7,'Test Cases'!$L$2:$L$211,"Blocked") | F7: =COUNTIFS('Test Cases'!$B$2:$B$211,$A7,'Test Cases'!$L$2:$L$211,"Not Run") | G7: =COUNTIFS('Test Cases'!$B$2:$B$211,$A7,'Test Cases'!$L$2:$L$211,"N/A") | H7: =IF(B7-G7-F7=0,"-",C7/(B7-G7-F7))
A8: How it works | B8: =COUNTIF('Test Cases'!$B$2:$B$211,$A8) | C8: =COUNTIFS('Test Cases'!$B$2:$B$211,$A8,'Test Cases'!$L$2:$L$211,"Pass") | D8: =COUNTIFS('Test Cases'!$B$2:$B$211,$A8,'Test Cases'!$L$2:$L$211,"Fail") | E8: =COUNTIFS('Test Cases'!$B$2:$B$211,$A8,'Test Cases'!$L$2:$L$211,"Blocked") | F8: =COUNTIFS('Test Cases'!$B$2:$B$211,$A8,'Test Cases'!$L$2:$L$211,"Not Run") | G8: =COUNTIFS('Test Cases'!$B$2:$B$211,$A8,'Test Cases'!$L$2:$L$211,"N/A") | H8: =IF(B8-G8-F8=0,"-",C8/(B8-G8-F8))
A9: Pricing | B9: =COUNTIF('Test Cases'!$B$2:$B$211,$A9) | C9: =COUNTIFS('Test Cases'!$B$2:$B$211,$A9,'Test Cases'!$L$2:$L$211,"Pass") | D9: =COUNTIFS('Test Cases'!$B$2:$B$211,$A9,'Test Cases'!$L$2:$L$211,"Fail") | E9: =COUNTIFS('Test Cases'!$B$2:$B$211,$A9,'Test Cases'!$L$2:$L$211,"Blocked") | F9: =COUNTIFS('Test Cases'!$B$2:$B$211,$A9,'Test Cases'!$L$2:$L$211,"Not Run") | G9: =COUNTIFS('Test Cases'!$B$2:$B$211,$A9,'Test Cases'!$L$2:$L$211,"N/A") | H9: =IF(B9-G9-F9=0,"-",C9/(B9-G9-F9))
A10: Custom box | B10: =COUNTIF('Test Cases'!$B$2:$B$211,$A10) | C10: =COUNTIFS('Test Cases'!$B$2:$B$211,$A10,'Test Cases'!$L$2:$L$211,"Pass") | D10: =COUNTIFS('Test Cases'!$B$2:$B$211,$A10,'Test Cases'!$L$2:$L$211,"Fail") | E10: =COUNTIFS('Test Cases'!$B$2:$B$211,$A10,'Test Cases'!$L$2:$L$211,"Blocked") | F10: =COUNTIFS('Test Cases'!$B$2:$B$211,$A10,'Test Cases'!$L$2:$L$211,"Not Run") | G10: =COUNTIFS('Test Cases'!$B$2:$B$211,$A10,'Test Cases'!$L$2:$L$211,"N/A") | H10: =IF(B10-G10-F10=0,"-",C10/(B10-G10-F10))
A11: Shop | B11: =COUNTIF('Test Cases'!$B$2:$B$211,$A11) | C11: =COUNTIFS('Test Cases'!$B$2:$B$211,$A11,'Test Cases'!$L$2:$L$211,"Pass") | D11: =COUNTIFS('Test Cases'!$B$2:$B$211,$A11,'Test Cases'!$L$2:$L$211,"Fail") | E11: =COUNTIFS('Test Cases'!$B$2:$B$211,$A11,'Test Cases'!$L$2:$L$211,"Blocked") | F11: =COUNTIFS('Test Cases'!$B$2:$B$211,$A11,'Test Cases'!$L$2:$L$211,"Not Run") | G11: =COUNTIFS('Test Cases'!$B$2:$B$211,$A11,'Test Cases'!$L$2:$L$211,"N/A") | H11: =IF(B11-G11-F11=0,"-",C11/(B11-G11-F11))
A12: Product page | B12: =COUNTIF('Test Cases'!$B$2:$B$211,$A12) | C12: =COUNTIFS('Test Cases'!$B$2:$B$211,$A12,'Test Cases'!$L$2:$L$211,"Pass") | D12: =COUNTIFS('Test Cases'!$B$2:$B$211,$A12,'Test Cases'!$L$2:$L$211,"Fail") | E12: =COUNTIFS('Test Cases'!$B$2:$B$211,$A12,'Test Cases'!$L$2:$L$211,"Blocked") | F12: =COUNTIFS('Test Cases'!$B$2:$B$211,$A12,'Test Cases'!$L$2:$L$211,"Not Run") | G12: =COUNTIFS('Test Cases'!$B$2:$B$211,$A12,'Test Cases'!$L$2:$L$211,"N/A") | H12: =IF(B12-G12-F12=0,"-",C12/(B12-G12-F12))
A13: Cart | B13: =COUNTIF('Test Cases'!$B$2:$B$211,$A13) | C13: =COUNTIFS('Test Cases'!$B$2:$B$211,$A13,'Test Cases'!$L$2:$L$211,"Pass") | D13: =COUNTIFS('Test Cases'!$B$2:$B$211,$A13,'Test Cases'!$L$2:$L$211,"Fail") | E13: =COUNTIFS('Test Cases'!$B$2:$B$211,$A13,'Test Cases'!$L$2:$L$211,"Blocked") | F13: =COUNTIFS('Test Cases'!$B$2:$B$211,$A13,'Test Cases'!$L$2:$L$211,"Not Run") | G13: =COUNTIFS('Test Cases'!$B$2:$B$211,$A13,'Test Cases'!$L$2:$L$211,"N/A") | H13: =IF(B13-G13-F13=0,"-",C13/(B13-G13-F13))
A14: Coupons | B14: =COUNTIF('Test Cases'!$B$2:$B$211,$A14) | C14: =COUNTIFS('Test Cases'!$B$2:$B$211,$A14,'Test Cases'!$L$2:$L$211,"Pass") | D14: =COUNTIFS('Test Cases'!$B$2:$B$211,$A14,'Test Cases'!$L$2:$L$211,"Fail") | E14: =COUNTIFS('Test Cases'!$B$2:$B$211,$A14,'Test Cases'!$L$2:$L$211,"Blocked") | F14: =COUNTIFS('Test Cases'!$B$2:$B$211,$A14,'Test Cases'!$L$2:$L$211,"Not Run") | G14: =COUNTIFS('Test Cases'!$B$2:$B$211,$A14,'Test Cases'!$L$2:$L$211,"N/A") | H14: =IF(B14-G14-F14=0,"-",C14/(B14-G14-F14))
A15: Account access | B15: =COUNTIF('Test Cases'!$B$2:$B$211,$A15) | C15: =COUNTIFS('Test Cases'!$B$2:$B$211,$A15,'Test Cases'!$L$2:$L$211,"Pass") | D15: =COUNTIFS('Test Cases'!$B$2:$B$211,$A15,'Test Cases'!$L$2:$L$211,"Fail") | E15: =COUNTIFS('Test Cases'!$B$2:$B$211,$A15,'Test Cases'!$L$2:$L$211,"Blocked") | F15: =COUNTIFS('Test Cases'!$B$2:$B$211,$A15,'Test Cases'!$L$2:$L$211,"Not Run") | G15: =COUNTIFS('Test Cases'!$B$2:$B$211,$A15,'Test Cases'!$L$2:$L$211,"N/A") | H15: =IF(B15-G15-F15=0,"-",C15/(B15-G15-F15))
A16: Checkout | B16: =COUNTIF('Test Cases'!$B$2:$B$211,$A16) | C16: =COUNTIFS('Test Cases'!$B$2:$B$211,$A16,'Test Cases'!$L$2:$L$211,"Pass") | D16: =COUNTIFS('Test Cases'!$B$2:$B$211,$A16,'Test Cases'!$L$2:$L$211,"Fail") | E16: =COUNTIFS('Test Cases'!$B$2:$B$211,$A16,'Test Cases'!$L$2:$L$211,"Blocked") | F16: =COUNTIFS('Test Cases'!$B$2:$B$211,$A16,'Test Cases'!$L$2:$L$211,"Not Run") | G16: =COUNTIFS('Test Cases'!$B$2:$B$211,$A16,'Test Cases'!$L$2:$L$211,"N/A") | H16: =IF(B16-G16-F16=0,"-",C16/(B16-G16-F16))
... A31: Security | B31: =COUNTIF('Test Cases'!$B$2:$B$211,$A31) | C31: =COUNTIFS('Test Cases'!$B$2:$B$211,$A31,'Test Cases'!$L$2:$L$211,"Pass") | D31: =COUNTIFS('Test Cases'!$B$2:$B$211,$A31,'Test Cases'!$L$2:$L$211,"Fail") | E31: =COUNTIFS('Test Cases'!$B$2:$B$211,$A31,'Test Cases'!$L$2:$L$211,"Blocked") | F31: =COUNTIFS('Test Cases'!$B$2:$B$211,$A31,'Test Cases'!$L$2:$L$211,"Not Run") | G31: =COUNTIFS('Test Cases'!$B$2:$B$211,$A31,'Test Cases'!$L$2:$L$211,"N/A") | H31: =IF(B31-G31-F31=0,"-",C31/(B31-G31-F31))
A32: Total | B32: =SUM(B5:B31) | C32: =SUM(C5:C31) | D32: =SUM(D5:D31) | E32: =SUM(E5:E31) | F32: =SUM(F5:F31) | G32: =SUM(G5:G31) | H32: =IF(B32-G32-F32=0,"-",C32/(B32-G32-F32))
A33: Pass rate = Pass ÷ (Total − N/A − Not Run)
A35: Priority | B35: Total | C35: Pass | D35: Fail | E35: Blocked | F35: Not Run
A36: P1 | B36: =COUNTIF('Test Cases'!$F$2:$F$211,$A36) | C36: =COUNTIFS('Test Cases'!$F$2:$F$211,$A36,'Test Cases'!$L$2:$L$211,"Pass") | D36: =COUNTIFS('Test Cases'!$F$2:$F$211,$A36,'Test Cases'!$L$2:$L$211,"Fail") | E36: =COUNTIFS('Test Cases'!$F$2:$F$211,$A36,'Test Cases'!$L$2:$L$211,"Blocked") | F36: =COUNTIFS('Test Cases'!$F$2:$F$211,$A36,'Test Cases'!$L$2:$L$211,"Not Run")
A37: P2 | B37: =COUNTIF('Test Cases'!$F$2:$F$211,$A37) | C37: =COUNTIFS('Test Cases'!$F$2:$F$211,$A37,'Test Cases'!$L$2:$L$211,"Pass") | D37: =COUNTIFS('Test Cases'!$F$2:$F$211,$A37,'Test Cases'!$L$2:$L$211,"Fail") | E37: =COUNTIFS('Test Cases'!$F$2:$F$211,$A37,'Test Cases'!$L$2:$L$211,"Blocked") | F37: =COUNTIFS('Test Cases'!$F$2:$F$211,$A37,'Test Cases'!$L$2:$L$211,"Not Run")
A38: P3 | B38: =COUNTIF('Test Cases'!$F$2:$F$211,$A38) | C38: =COUNTIFS('Test Cases'!$F$2:$F$211,$A38,'Test Cases'!$L$2:$L$211,"Pass") | D38: =COUNTIFS('Test Cases'!$F$2:$F$211,$A38,'Test Cases'!$L$2:$L$211,"Fail") | E38: =COUNTIFS('Test Cases'!$F$2:$F$211,$A38,'Test Cases'!$L$2:$L$211,"Blocked") | F38: =COUNTIFS('Test Cases'!$F$2:$F$211,$A38,'Test Cases'!$L$2:$L$211,"Not Run")
A39: P4 | B39: =COUNTIF('Test Cases'!$F$2:$F$211,$A39) | C39: =COUNTIFS('Test Cases'!$F$2:$F$211,$A39,'Test Cases'!$L$2:$L$211,"Pass") | D39: =COUNTIFS('Test Cases'!$F$2:$F$211,$A39,'Test Cases'!$L$2:$L$211,"Fail") | E39: =COUNTIFS('Test Cases'!$F$2:$F$211,$A39,'Test Cases'!$L$2:$L$211,"Blocked") | F39: =COUNTIFS('Test Cases'!$F$2:$F$211,$A39,'Test Cases'!$L$2:$L$211,"Not Run")
A41: Defects by severity | B41: Count | C41: Open
A42: Blocker | B42: =COUNTIF('Known Defects'!$B$2:$B$29,$A42) | C42: =COUNTIFS('Known Defects'!$B$2:$B$29,$A42,'Known Defects'!$L$2:$L$29,"Open")
A43: Critical | B43: =COUNTIF('Known Defects'!$B$2:$B$29,$A43) | C43: =COUNTIFS('Known Defects'!$B$2:$B$29,$A43,'Known Defects'!$L$2:$L$29,"Open")
A44: High | B44: =COUNTIF('Known Defects'!$B$2:$B$29,$A44) | C44: =COUNTIFS('Known Defects'!$B$2:$B$29,$A44,'Known Defects'!$L$2:$L$29,"Open")
A45: Medium | B45: =COUNTIF('Known Defects'!$B$2:$B$29,$A45) | C45: =COUNTIFS('Known Defects'!$B$2:$B$29,$A45,'Known Defects'!$L$2:$L$29,"Open")
A46: Low | B46: =COUNTIF('Known Defects'!$B$2:$B$29,$A46) | C46: =COUNTIFS('Known Defects'!$B$2:$B$29,$A46,'Known Defects'!$L$2:$L$29,"Open")

Sheet Test Cases
A1: ID | B1: Module | C1: Feature | D1: Title | E1: Type | F1: Priority | G1: Preconditions | H1: Test Data | I1: Steps | J1: Expected Result | K1: Known Defect | L1: Status | M1: Actual Result | N1: Defect ID | O1: Tester | P1: Run Date | Q1: Browser / Device
A2: TC-WEB-001 | B2: Global | C2: Header | D2: Header shows logo, nav links, Sign In, Subscribe and language switch | E2: UI | F2: P2 | G2: Guest, clean browser (no localStorage) | I2: 1. Open / | J2: Logo, How it works, Pricing, Shop, Blog, Sign In, Subscribe and EN/KA switch are visible and aligned | L2: Pass | M2: As expected | O2: TK | P2: 08.10.2026 | Q2: Chrome / macOS
A3: TC-WEB-002 | B3: Global | C3: Header | D3: Each nav link opens the right page and is highlighted as active | E3: Functional | F3: P2 | G3: Guest, clean browser (no localStorage) | I3: 1. Click How it works, Pricing, Shop, Blog in turn | J3: Each opens /how-it-works, /prices, /shop, /blog and that link is shown as active (teal, bold) | L3: Not Run
A4: TC-WEB-003 | B4: Global | C4: Header | D4: Logo returns to the homepage from any page | E4: Functional | F4: P3 | G4: Guest, clean browser (no localStorage) | I4: 1. Open /shop 2. Click the Pupbox logo | J4: Homepage / opens | L4: Not Run
A5: TC-WEB-004 | B5: Global | C5: Header | D5: Header stays fixed (sticky) while scrolling | E5: UI | F5: P4 | G5: Guest, clean browser (no localStorage) | I5: 1. Open / and scroll to the bottom | J5: Header remains visible at the top with a translucent background | L5: Not Run
A6: TC-WEB-005 | B6: Global | C6: Header | D6: Cart is reachable from the header and shows the item count | E6: Functional | F6: P1 | G6: Guest, clean browser (no localStorage); 2 products in cart | I6: 1. Add 2 products to cart 2. Look at the header on any page | J6: A cart icon with badge "2" is visible and opens /cart | K6: D-06 | L6: Not Run
A7: TC-WEB-006 | B7: Global | C7: Header | D7: Header reflects signed-in state | E7: Functional | F7: P2 | G7: Signed in as a customer | I7: 1. Sign in 2. Look at the header | J7: "Sign In" is replaced by account access (e.g. My account / Sign out) | K7: D-06 | L7: Not Run
A8: TC-WEB-007 | B8: Global | C8: Navigation | D8: Mobile navigation exists at phone width | E8: Compatibility | F8: P1 | G8: Guest, clean browser (no localStorage) | H8: Viewport 375×812 | I8: 1. Open / at 375px width 2. Try to reach Pricing, Shop, Blog, Sign In | J8: A menu (e.g. hamburger) gives access to every nav link and Sign In | K8: D-07 | L8: Not Run
A9: TC-WEB-008 | B9: Global | C9: Navigation | D9: Unknown URL shows a 404 page | E9: Negative | F9: P3 | G9: Guest, clean browser (no localStorage) | H9: /this-page-does-not-exist | I9: 1. Open the URL | J9: A branded 404 page with a way back home; HTTP status 404 | L9: Not Run
A10: TC-WEB-009 | B10: Global | C10: Navigation | D10: Browser Back/Forward keep page state sensible | E10: Functional | F10: P3 | G10: Guest, clean browser (no localStorage) | I10: 1. Open /shop?category=toys 2. Open a product 3. Press Back | J10: Returns to the filtered shop list with the same filter | L10: Not Run
A11: TC-WEB-010 | B11: Global | C11: Layout | D11: Page has a footer with legal and contact links | E11: UI | F11: P3 | G11: Guest, clean browser (no localStorage) | I11: 1. Scroll to the bottom of / | J11: Footer shows Terms, Privacy, Contact and social links that open the right pages | L11: Not Run
A12: TC-WEB-011 | B12: Global | C12: Errors | D12: Site degrades gracefully when the API is down | E12: Negative | F12: P2 | G12: API stopped (Ctrl-C the API process) | I12: 1. Open /, /prices, /shop, /cart | J12: Pages render with friendly empty/error states, no crash or blank screen | L12: Not Run
A13: TC-WEB-012 | B13: Localization | C13: Language | D13: Default language is Georgian on first visit | E13: Localization | F13: P2 | G13: Guest, clean browser (no localStorage) | I13: 1. Open / in a fresh browser | J13: Content is in Georgian; switch shows KA | L13: Not Run
A14: TC-WEB-013 | B14: Localization | C14: Language | D14: Switch to English and back | E14: Localization | F14: P2 | G14: Guest, clean browser (no localStorage) | I14: 1. Open the EN/KA menu 2. Choose English 3. Choose ქართული | J14: All header and page copy switches language each time without reload errors | L14: Not Run
A15: TC-WEB-014 | B15: Localization | C15: Language | D15: Language choice persists across pages and reloads | E15: Localization | F15: P2 | G15: Guest, clean browser (no localStorage) | I15: 1. Choose English 2. Navigate to /prices 3. Reload | J15: Site stays in English | L15: Not Run
A16: TC-WEB-015 | B16: Localization | C16: Language | D16: Language menu works by touch and keyboard | E16: Accessibility | F16: P2 | G16: Guest, clean browser (no localStorage) | H16: Phone or keyboard only | I16: 1. Tap the EN/KA button on a phone 2. Tab to it and press Enter | J16: Menu opens and options can be chosen in both cases | K16: D-08 | L16: Not Run
A17: TC-WEB-016 | B17: Localization | C17: Coverage | D17: Every customer page is translated when Georgian is selected | E17: Localization | F17: P2 | G17: Guest, clean browser (no localStorage) | H17: Pages: /cart, /checkout, /shop, /shop/[slug], /login, /register, /account/*, /checkout/thank-you, /gift/[token] | I17: 1. Select ქართული 2. Visit each page listed | J17: No English UI strings remain (buttons, labels, errors, empty states) | K17: D-15 | L17: Not Run
A18: TC-WEB-017 | B18: Localization | C18: Copy | D18: Georgian brand wording is correct in title, social preview and hero badge | E18: Localization | F18: P2 | G18: Guest, clean browser (no localStorage) | I18: 1. Check the browser tab title on / 2. Check the hero badge text 3. View page source for og:title | J18: Text says "ყოველთვიური ყუთის გამოწერა" (box), not "კუთხის" (corner) | K18: D-14 | L18: Not Run
A19: TC-WEB-018 | B19: Localization | C19: Copy | D19: Plan benefits are translated in Georgian | E19: Localization | F19: P3 | G19: Guest, clean browser (no localStorage) | I19: 1. Select ქართული 2. Open /prices | J19: Each benefit line on every plan card is in Georgian | L19: Not Run
A20: TC-WEB-019 | B20: Localization | C20: Formatting | D20: Prices use ₾ and consistent decimals in both languages | E20: Localization | F20: P3 | G20: Guest, clean browser (no localStorage) | I20: 1. Compare prices on /prices, /cart, /checkout in KA and EN | J20: Same amounts and format (₾ symbol, 2 decimals where shown) | K20: D-16 | L20: Not Run
A21: TC-WEB-020 | B21: Localization | C21: Formatting | D21: Long Georgian strings do not overflow buttons or cards | E21: UI | F21: P3 | G21: Guest, clean browser (no localStorage) | H21: Viewport 375px and 1280px | I21: 1. Select ქართული 2. Review buttons, plan cards, nav | J21: No clipped or overlapping text | L21: Not Run
A22: TC-WEB-021 | B22: Homepage | C22: Hero | D22: Hero shows heading, description and 3 CTAs | E22: UI | F22: P2 | G22: Guest, clean browser (no localStorage) | I22: 1. Open / | J22: Heading, text, "Start Your Subscription", "Give as a Gift" and "See How It Works" are visible | L22: Not Run
A23: TC-WEB-022 | B23: Homepage | C23: Hero | D23: "Start Your Subscription" opens pricing | E23: Functional | F23: P1 | G23: Guest, clean browser (no localStorage) | I23: 1. Click Start Your Subscription | J23: /prices opens in "For my dog" mode | L23: Not Run
A24: TC-WEB-023 | B24: Homepage | C24: Hero | D24: "Give as a Gift" opens pricing in gift mode | E24: Functional | F24: P2 | G24: Guest, clean browser (no localStorage) | I24: 1. Click Give as a Gift | J24: /prices?gift=true opens with the Gift toggle selected and gift banner shown | L24: Not Run
A25: TC-WEB-024 | B25: Homepage | C25: Hero | D25: "See How It Works" opens the explainer | E25: Functional | F25: P3 | G25: Guest, clean browser (no localStorage) | I25: 1. Click See How It Works | J25: /how-it-works opens | L25: Not Run
A26: TC-WEB-025 | B26: Homepage | C26: Content | D26: Stats, box contents and plan sections load | E26: Functional | F26: P2 | G26: Guest, clean browser (no localStorage) | I26: 1. Scroll through / | J26: All sections render with real plan data and no placeholder/undefined text | L26: Not Run
A27: TC-WEB-026 | B27: Homepage | C27: Content | D27: Plans on the homepage match /prices | E27: Functional | F27: P2 | G27: Guest, clean browser (no localStorage) | I27: 1. Compare plan names and prices on / and /prices | J27: Same plans, same prices | L27: Not Run
A28: TC-WEB-027 | B28: Homepage | C28: Animation | D28: Entrance animations do not hide content | E28: UI | F28: P4 | G28: Guest, clean browser (no localStorage) | H28: Reduced motion ON in OS | I28: 1. Enable "Reduce motion" 2. Open / | J28: All content visible; animations reduced or skipped | L28: Not Run
A29: TC-WEB-028 | B29: How it works | C29: Page | D29: Steps and FAQ render and CTA leads to pricing | E29: Functional | F29: P3 | G29: Guest, clean browser (no localStorage) | I29: 1. Open /how-it-works 2. Click the main CTA | J29: All steps visible; CTA opens /prices | L29: Not Run
A30: TC-WEB-029 | B30: Pricing | C30: Plans | D30: All active plans are listed with name, total and monthly price | E30: Functional | F30: P1 | G30: Guest, clean browser (no localStorage) | H30: Expected plans: 1 Month ₾49.99, 3 Months ₾134.99, 6 Months ₾255, 1 Year ₾480 | I30: 1. Open /prices | J30: Every active plan appears with correct total, ≈ per-month price and benefits | L30: Not Run
A31: TC-WEB-030 | B31: Pricing | C31: Plans | D31: Inactive or test plans are not offered to customers | E31: Functional | F31: P1 | G31: Guest, clean browser (no localStorage) | H31: Plan "3 month" ₾150 is a leftover test | I31: 1. Open /prices | J31: Only intended plans are shown; "3 month" ₾150 is not offered | K31: D-24 | L31: Not Run
A32: TC-WEB-031 | B32: Pricing | C32: Plans | D32: Plan prices are shown exactly, not rounded | E32: Functional | F32: P2 | G32: Guest, clean browser (no localStorage) | H32: 3 Months = ₾134.99 | I32: 1. Open /prices 2. Read the 3 Months card | J32: Card shows ₾134.99 (same as in cart), not ₾135 | K32: D-16 | L32: Not Run
A33: TC-WEB-032 | B33: Pricing | C33: Badges | D33: "Most Popular" and "Best Value" badges display on the right plans | E33: Functional | F33: P2 | G33: Badges set in admin | I33: 1. Open /prices | J33: Plans with a badge in admin show the badge ribbon and highlighted border | K33: D-01 | L33: Not Run
A34: TC-WEB-033 | B34: Pricing | C34: Plans | D34: Discount line only shows for discounted plans | E34: UI | F34: P3 | G34: Guest, clean browser (no localStorage) | I34: 1. Open /prices | J34: "Save X% vs monthly" appears only where a discount exists; no stray "0" text | L34: Not Run
A35: TC-WEB-034 | B35: Pricing | C35: Plans | D35: Plans are ordered as set in admin (sort order) | E35: Functional | F35: P3 | G35: Sort order set in admin | I35: 1. Change sort order in admin 2. Reload /prices | J35: Order on the site follows admin | L35: Not Run
A36: TC-WEB-035 | B36: Pricing | C36: Toggle | D36: Switch between "For my dog" and "Gift" | E36: Functional | F36: P2 | G36: Guest, clean browser (no localStorage) | I36: 1. Click Gift 2. Click For my dog | J36: Gift shows amber styling, gift banner and "Gift card & personalised message"; switching back restores normal cards | L36: Not Run
A37: TC-WEB-036 | B37: Pricing | C37: Choose | D37: Choosing a plan adds it to cart and opens checkout | E37: Functional | F37: P1 | G37: Guest, clean browser (no localStorage) | H37: 1 Month | I37: 1. Click the 1 Month card | J37: Plan added to cart (1 item) and /checkout opens | L37: Not Run
A38: TC-WEB-037 | B38: Pricing | C38: Choose | D38: Choosing a plan in gift mode opens gift checkout | E38: Functional | F38: P1 | G38: Guest, clean browser (no localStorage) | H38: 3 Months | I38: 1. Select Gift 2. Click 3 Months | J38: /checkout?gift=true opens with steps Account → Gift Details → Delivery → Review | L38: Not Run
A39: TC-WEB-038 | B39: Pricing | C39: Choose | D39: Choosing a second plan does not leave two plans in the cart unintentionally | E39: Edge | F39: P2 | G39: Guest, clean browser (no localStorage) | I39: 1. Choose 1 Month 2. Go back to /prices 3. Choose 6 Months 4. Open /cart | J39: Clear behaviour: plan replaced, or both shown with a warning; never a silent double charge | L39: Not Run
A40: TC-WEB-039 | B40: Pricing | C40: Choose | D40: Double-clicking a plan adds it only once | E40: Edge | F40: P2 | G40: Guest, clean browser (no localStorage) | I40: 1. Double-click a plan card quickly | J40: Only one plan in cart | L40: Not Run
...

Sheet Known Defects
A1: ID | B1: Severity | C1: Area | D1: Title | E1: Steps to Reproduce | F1: Expected | G1: Actual | H1: Evidence | I1: Confidence | J1: Linked Test Cases | K1: Owner | L1: Fix Status
A2: D-01 | B2: High | C2: Pricing | D2: Plan badges never show on the website | E2: 1. In admin, give a plan the "Most Popular" or "Best Value" badge 2. Open /prices | F2: Badge ribbon and highlight on that plan | G2: No badge or highlight. Admin saves "Most Popular"/"Best Value"; website checks for "popular"/"best_value" | H2: Confirmed live: API returns badge "Most Popular" (on "3 month") and "Best Value" (on "1 Year"). Code: apps/web/src/components/PlanCard.tsx (isPopular/isBest) | I2: Confirmed | J2: TC-WEB-032 | K2: Commit 64b7f57 (fix/launch-critical) | L2: Fixed
A3: D-02 | B3: Critical | C3: Custom box | D3: "Order Custom Box" does not add the chosen items to the cart | E3: 1. /prices → Build your own box 2. Pick 3+ items 3. Click Order Custom Box | F3: Checkout contains the custom box at the shown price | G3: Goes to /checkout?custom=true with the cart unchanged (empty or previous items). The catalogue is hard-coded, not real products | H3: Code: apps/web/src/app/prices/CustomBox.tsx (router.push only); checkout ignores the custom param | I3: From code — verify | J3: TC-WEB-047 | K3: Commit edb99f0 (removed) (fix/launch-critical) | L3: Fixed
A4: D-03 | B4: Critical | C4: Cart / Checkout | D4: Guest cart is lost when the customer signs in or creates an account | E4: 1. As guest add items 2. At checkout create account or sign in 3. Continue to review / place order | F4: Same items, now on the account | G4: Cart is looked up by user after login and by session before; there is no merge, so the account cart is empty and the order fails or shows wrong items | H4: Code: apps/api/src/modules/cart/cart.service.ts getOrCreate (userId OR sessionId, no merge); checkout does not refresh cart after login | I4: From code — verify | J4: TC-WEB-080, TC-WEB-113, TC-WEB-114 | K4: Commit d59ab61 (fix/launch-critical) | L4: Fixed
A5: D-04 | B5: High | C5: Payment | D5: Thank-you page says "Payment confirmed!" without a payment | E5: Open /checkout/thank-you (no params) or ?payment_status=processing | F5: Neutral or pending message | G5: "🎉 Payment confirmed!" — success is assumed for missing or unknown statuses | H5: Code: apps/web/src/app/checkout/thank-you/page.tsx (isSuccess = approved || !paymentStatus; unknown values fall through) | I5: From code | J5: TC-WEB-146 | K5: Commit 28d3942 (fix/launch-critical) | L5: Fixed
A6: D-05 | B6: Medium | C6: SEO | D6: sitemap.xml lists no products, categories or posts | E6: Open /sitemap.xml | F6: All public URLs | G6: Only 4 static URLs. Code expects products.products; API returns items | H6: Confirmed live: 4 <loc> entries with 6 products and 5 categories in DB. Code: apps/web/src/app/sitemap.ts | I6: Confirmed | J6: TC-WEB-191 | K6: Commit fe33a36 (fix/launch-critical) | L6: Fixed
A7: D-06 | B7: High | C7: Header | D7: No cart link and no signed-in state in the header | E7: Add to cart, or sign in, then look at the header | F7: Cart icon with count; account menu when signed in | G7: No cart access except via product page button; "Sign In" always shown. CartIcon component exists but is not used | H7: Code: apps/web/src/components/Header.tsx; CartIcon.tsx unused | I7: From code | J7: TC-WEB-005, TC-WEB-006 | K7: Commit 64b7f57 (fix/launch-critical) | L7: Fixed
A8: D-07 | B8: High | C8: Mobile | D8: No navigation on phones | E8: Open the site at 375px width | F8: Menu button with all links and Sign In | G8: Nav hidden below 768px, Sign In hidden below 640px, no replacement menu | H8: Code: Header.tsx (hidden md:flex / hidden sm:block) | I8: From code | J8: TC-WEB-007, TC-WEB-201 | K8: Commit 64b7f57 (fix/launch-critical) | L8: Fixed
A9: D-08 | B9: Medium | C9: Localization | D9: Language menu only opens on mouse hover | E9: Tap EN/KA on a phone, or Tab + Enter | F9: Menu opens | G9: Opens via CSS :hover only; not keyboard or touch friendly | H9: Code: Header.tsx (group-hover) | I9: From code | J9: TC-WEB-015 | K9: Commit 64b7f57 (fix/launch-critical) | L9: Fixed
A10: D-09 | B10: Low | C10: Shop | D10: Default sort labelled "Price: Low → High" but applies no sort | E10: Open /shop, read sort dropdown | F10: Default reads "Featured" or similar | G10: First option and "price_asc" share the same label | H10: Code: apps/web/src/app/shop/ShopControls.tsx | I10: From code | J10: TC-WEB-059 | K10: Commit 394d70a (fix/launch-critical) | L10: Fixed
A11: D-10 | B11: Medium | C11: Shop | D11: Sort, brand filter and count only apply to the current page | E11: Have more products than one page; sort or filter | F11: Global sort/filter and total count | G11: Sorting/brand filter run in the browser on one page of results; count shows that page only | H11: Code: apps/web/src/app/shop/page.tsx | I11: From code | J11: TC-WEB-060, TC-WEB-062 | K11: Commit b5cba6d (fix/launch-critical) | L11: Fixed
A12: D-11 | B12: High | C12: Checkout | D12: Delivery address fields are not validated | E12: At delivery step leave name/phone/city/address empty, pick a method, Continue | F12: Field errors; cannot continue | G12: Proceeds to review and order can be placed with an empty address | H12: Code: checkout/page.tsx handleDeliveryStep checks method only | I12: From code | J12: TC-WEB-121, TC-WEB-122 | K12: Commit 28d3942 (fix/launch-critical) | L12: Fixed
... A24: D-23 | B24: Low | C24: SEO | D24: robots.txt misses /checkout (no slash), /gift, /login, /register | E24: Open /robots.txt | F24: Private flows disallowed | G24: Only /account/, /cart, /checkout/, /api/ disallowed | H24: Confirmed live: /robots.txt | I24: Confirmed | J24: TC-WEB-192 | K24: Commit fe33a36 (fix/launch-critical) | L24: Fixed
A25: D-24 | B25: Medium | C25: Data | D25: Test data visible to customers | E25: Open /prices and /shop | F25: Only real plans and categories | G25: Plan "3 month" ₾150 is live with the "Most Popular" badge; category "test" (slug t) in shop sidebar | H25: Confirmed live: public API | I25: Confirmed | J25: TC-WEB-030, TC-WEB-052 | L25: Open
A26: D-25 | B26: Blocker | C26: Payment | D26: Payments cannot be taken — Flitt keys are empty | E26: Click Pay Now on any order | F26: Redirect to Flitt | G26: Initiation fails ("Failed to initiate payment") | H26: Handover SETUP-AND-KEYS.md §4: FLITT_MERCHANT_ID/SECRET/WEBHOOK empty | I26: Known | J26: TC-WEB-142, TC-WEB-143 | L26: Open
A27: D-26 | B27: Low | C27: Account | D27: Two headers on My Orders and Referrals | E27: Open /account/orders | F27: One header | G27: Global header plus a page header with its own logo/nav | H27: Code: account/orders/page.tsx, account/referrals/page.tsx | I27: From code | J27: TC-WEB-160 | K27: Commit a705aba (fix/launch-critical) | L27: Fixed
A28: D-29 | B28: Low | C28: Checkout | D28: Signed-in customer must retype name and phone | E28: Sign in, go to delivery step | F28: Pre-filled from profile | G28: Fields empty | H28: Code: checkout/page.tsx | I28: From code | J28: TC-WEB-127 | K28: Commit 28d3942 (fix/launch-critical) | L28: Fixed
A29: D-30 | B29: High | C29: Checkout | D29: Plans promising free delivery may still be charged delivery | E29: Put a plan with "Free delivery" in cart, reach delivery step | F29: ₾0 delivery for the plan | G29: Delivery methods are priced on subtotal only (Standard ₾5.99, Express ₾12.99 at ₾50); no free option shown for plans | H29: Confirmed live: /cart/delivery-methods?total=50 has no free method. Plan cards promise free delivery | I29: Confirmed — needs product decision | J29: TC-WEB-126 | K29: Commit d59ab61 (fix/launch-critical) | L29: Fixed
A30: D-31 | B30: High | C30: Payment | D30: A declined payment cancels the order; the customer cannot retry | E30: 1. Place an order 2. Pay with a declined card 3. Try again from the result page or My Orders | F30: The order waits for payment and can be retried (stock held until it expires) | G30: Webhook sets the order CANCELLED and releases stock; cart was already emptied, so the customer must rebuild it | H30: Code: apps/api/src/modules/payments/payments.service.ts handleWebhook (paymentStatus FAILED → CANCELLED) | I30: From code — needs Flitt sandbox | K30: Commit 38c0974 (fix/launch-critical) — verify with Flitt sandbox once keys exist (D-25) | L30: Fixed

Sheet Test Data
A1: Item | B1: Value | C1: Why it matters | D1: Used by
A2: Customer A (create) | B2: qa.customer.a+<date>@example.com · password of 8+ chars | C2: Main signed-in customer | D2: Account, checkout, orders
A3: Customer B (create) | B3: qa.customer.b+<date>@example.com | C3: Privacy / cross-account checks | D3: Cart privacy, security
A4: Gift recipient (create) | B4: qa.gift.recipient+<date>@example.com | C4: Claims a gifted subscription | D4: Gift claim
A5: Product — normal stock | B5: blueberry-biscuits (180 in stock) | C5: Happy-path add to cart | D5: Product page, cart
A6: Product — low stock | B6: chicken-jerky-treats (3 in stock) | C6: Low stock badge, quantity cap | D6: Shop, product page
A7: Product — out of stock | B7: rope-tug-toy (0 in stock) | C7: Disabled Add to Cart | D7: Shop, product page
A8: Plans | B8: 1 Month ₾49.99 · 3 Months ₾134.99 · 6 Months ₾255 · 1 Year ₾480 | C8: Expected live plans | D8: Pricing, checkout
A9: Plan — leftover test | B9: "3 month" ₾150 (badge Most Popular) | C9: Should not be offered (D-24) | D9: Pricing
A10: Delivery methods | B10: Standard ₾5.99 · Express ₾12.99 (no free option at ₾50) | C10: Totals and free-delivery promise (D-30) | D10: Checkout
A11: Coupons (create in admin) | B11: TEST10 10% · FIVE ₾5 fixed · EXPIRED (past date) · MIN100 (min ₾100) · ONCE (max uses 1) · BIG100 ₾100 fixed | C11: None exist today | D11: Coupons
A12: Categories | B12: Treats, Toys, Accessories, Grooming (+ junk "test") | C12: Filters | D12: Shop
... A15: Viewports | B15: 375×812 · 768×1024 · 1280×800 · 1920×1080 | C15: Responsive layout | D15: Responsive
